<?xml version="1.0" encoding="utf-8"?>
<!-- This URDF was automatically created by SolidWorks to URDF Exporter! Originally created by Stephen Brawner (brawner@gmail.com) 
     Commit Version: 1.6.0-4-g7f85cfe  Build Version: 1.6.7995.38578
     For more information, please see http://wiki.ros.org/sw_urdf_exporter -->
<robot
  name="ARMYPR6">
  <link
    name="base_link">
    <inertial>
      <origin
        xyz="0.0381708341809766 -0.00140666618573904 0.106286010737939"
        rpy="0 0 0" />
      <mass
        value="3.44766136170682" />
      <inertia
        ixx="0.013723684919501"
        ixy="-0.000589844407732805"
        ixz="-0.000265795178525529"
        iyy="0.0120078200354364"
        iyz="-0.00170526761308872"
        izz="0.0109946645922308" />
    </inertial>
    <visual>
      <origin
        xyz="0 0 0"
        rpy="0 0 0" />
      <geometry>
        <mesh
          filename="package://meshes/base_link.STL" />
      </geometry>
      <material
        name="">
        <color
          rgba="0.792156862745098 0.819607843137255 0.933333333333333 1" />
      </material>
    </visual>
    <collision>
      <origin
        xyz="0 0 0"
        rpy="0 0 0" />
      <geometry>
        <mesh
          filename="package://meshes/base_link.STL" />
      </geometry>
    </collision>
  </link>
  <link
    name="turntable">
    <inertial>
      <origin
        xyz="-0.00267730480039297 -0.00258676298943122 0.0234823964354525"
        rpy="0 0 0" />
      <mass
        value="2.3506402744061" />
      <inertia
        ixx="0.00437347444848986"
        ixy="-1.2640423499503E-08"
        ixz="-4.51937995301733E-05"
        iyy="0.00666578057039286"
        iyz="-6.87805063673265E-09"
        izz="0.00912722709891156" />
    </inertial>
    <visual>
      <origin
        xyz="0 0 0"
        rpy="0 0 0" />
      <geometry>
        <mesh
          filename="package://meshes/turntable.STL" />
      </geometry>
      <material
        name="">
        <color
          rgba="0.650980392156863 0.619607843137255 0.588235294117647 1" />
      </material>
    </visual>
    <collision>
      <origin
        xyz="0 0 0"
        rpy="0 0 0" />
      <geometry>
        <mesh
          filename="package://meshes/turntable.STL" />
      </geometry>
    </collision>
  </link>
  <joint
    name="turntablejoint"
    type="revolute">
    <origin
      xyz="0.26945 0 0.216"
      rpy="0 0 0" />
    <parent
      link="base_link" />
    <child
      link="turntable" />
    <axis
      xyz="0 0 -1" />
    <limit
      lower="-2"
      upper="2"
      effort="0"
      velocity="0" />
  </joint>
  <link
    name="link1">
    <inertial>
      <origin
        xyz="0.052129499090007 -0.00165361926087013 0.139664312313907"
        rpy="0 0 0" />
      <mass
        value="2.86881846288643" />
      <inertia
        ixx="0.0233096019749734"
        ixy="6.2489688091546E-07"
        ixz="-0.00824350432962109"
        iyy="0.027636645913229"
        iyz="4.79039522240276E-08"
        izz="0.00556962147507105" />
    </inertial>
    <visual>
      <origin
        xyz="0 0 0"
        rpy="0 0 0" />
      <geometry>
        <mesh
          filename="package://meshes/link1.STL" />
      </geometry>
      <material
        name="">
        <color
          rgba="0.792156862745098 0.819607843137255 0.933333333333333 1" />
      </material>
    </visual>
    <collision>
      <origin
        xyz="0 0 0"
        rpy="0 0 0" />
      <geometry>
        <mesh
          filename="package://meshes/link1.STL" />
      </geometry>
    </collision>
  </link>
  <joint
    name="joint1"
    type="revolute">
    <origin
      xyz="0.08505 0 0.15172"
      rpy="0 0 0" />
    <parent
      link="turntable" />
    <child
      link="link1" />
    <axis
      xyz="0 -1 0" />
    <limit
      lower="-2"
      upper="2"
      effort="0"
      velocity="0" />
  </joint>
  <link
    name="link2">
    <inertial>
      <origin
        xyz="0.0467437101668375 -0.00656844946709717 0.0263225251722374"
        rpy="0 0 0" />
      <mass
        value="1.4157165117551" />
      <inertia
        ixx="0.00110534289728777"
        ixy="1.09570322763697E-07"
        ixz="-0.000442330019281762"
        iyy="0.00215335440039908"
        iyz="7.26419563315174E-08"
        izz="0.00170993349276108" />
    </inertial>
    <visual>
      <origin
        xyz="0 0 0"
        rpy="0 0 0" />
      <geometry>
        <mesh
          filename="package://meshes/link2.STL" />
      </geometry>
      <material
        name="">
        <color
          rgba="0.796078431372549 0.823529411764706 0.937254901960784 1" />
      </material>
    </visual>
    <collision>
      <origin
        xyz="0 0 0"
        rpy="0 0 0" />
      <geometry>
        <mesh
          filename="package://meshes/link2.STL" />
      </geometry>
    </collision>
  </link>
  <joint
    name="joint2"
    type="revolute">
    <origin
      xyz="0.16161 -0.0165 0.39308"
      rpy="0 0 0" />
    <parent
      link="link1" />
    <child
      link="link2" />
    <axis
      xyz="0 -1 0" />
    <limit
      lower="-2"
      upper="2"
      effort="0"
      velocity="0" />
  </joint>
  <link
    name="pitch">
    <inertial>
      <origin
        xyz="0.0462550131939434 -0.00508561185348336 0.0244700814503312"
        rpy="0 0 0" />
      <mass
        value="0.424370516791685" />
      <inertia
        ixx="0.000117194373237424"
        ixy="6.92723147131335E-08"
        ixz="-1.8695760875076E-05"
        iyy="0.000109416182432902"
        iyz="2.19434071485635E-08"
        izz="0.000142961084720061" />
    </inertial>
    <visual>
      <origin
        xyz="0 0 0"
        rpy="0 0 0" />
      <geometry>
        <mesh
          filename="package://meshes/pitch.STL" />
      </geometry>
      <material
        name="">
        <color
          rgba="0.776470588235294 0.756862745098039 0.737254901960784 1" />
      </material>
    </visual>
    <collision>
      <origin
        xyz="0 0 0"
        rpy="0 0 0" />
      <geometry>
        <mesh
          filename="package://meshes/pitch.STL" />
      </geometry>
    </collision>
  </link>
  <joint
    name="pitchJoint"
    type="revolute">
    <origin
      xyz="0.19676 0.016444 0.10409"
      rpy="0 0 0" />
    <parent
      link="link2" />
    <child
      link="pitch" />
    <axis
      xyz="0 1 0" />
    <limit
      lower="-2"
      upper="2"
      effort="0"
      velocity="0" />
  </joint>
  <link
    name="yaw">
    <inertial>
      <origin
        xyz="0.0447240740582902 -0.00910187074205612 0.0179740828266273"
        rpy="0 0 0" />
      <mass
        value="0.416375076239649" />
      <inertia
        ixx="0.000137581552998124"
        ixy="2.0020276327758E-07"
        ixz="1.84727717808806E-05"
        iyy="0.000122119326134642"
        iyz="-9.89478322727336E-08"
        izz="0.00011246641748972" />
    </inertial>
    <visual>
      <origin
        xyz="0 0 0"
        rpy="0 0 0" />
      <geometry>
        <mesh
          filename="package://meshes/yaw.STL" />
      </geometry>
      <material
        name="">
        <color
          rgba="0.898039215686275 0.917647058823529 0.929411764705882 1" />
      </material>
    </visual>
    <collision>
      <origin
        xyz="0 0 0"
        rpy="0 0 0" />
      <geometry>
        <mesh
          filename="package://meshes/yaw.STL" />
      </geometry>
    </collision>
  </link>
  <joint
    name="yawjoint"
    type="revolute">
    <origin
      xyz="0.095579 -0.00064427 0.0505"
      rpy="0 0 0" />
    <parent
      link="pitch" />
    <child
      link="yaw" />
    <axis
      xyz="-0.46762 0 0.88393" />
    <limit
      lower="-2"
      upper="2"
      effort="0"
      velocity="0" />
  </joint>
  <link
    name="roll">
    <inertial>
      <origin
        xyz="0.0783795845305626 -0.0145129245859908 0.0413814652187382"
        rpy="0 0 0" />
      <mass
        value="0.695670819953184" />
      <inertia
        ixx="0.000792357459929206"
        ixy="-4.95718699175563E-05"
        ixz="-0.000184554624849212"
        iyy="0.000694117662937758"
        iyz="-2.63310013045663E-05"
        izz="0.00104238963794675" />
    </inertial>
    <visual>
      <origin
        xyz="0 0 0"
        rpy="0 0 0" />
      <geometry>
        <mesh
          filename="package://meshes/roll.STL" />
      </geometry>
      <material
        name="">
        <color
          rgba="0.650980392156863 0.619607843137255 0.588235294117647 1" />
      </material>
    </visual>
    <collision>
      <origin
        xyz="0 0 0"
        rpy="0 0 0" />
      <geometry>
        <mesh
          filename="package://meshes/roll.STL" />
      </geometry>
    </collision>
  </link>
  <joint
    name="roll joint"
    type="revolute">
    <origin
      xyz="0.06953 -0.042517 0.035491"
      rpy="0 0 0" />
    <parent
      link="yaw" />
    <child
      link="roll" />
    <axis
      xyz="-0.88393 0 -0.46762" />
    <limit
      lower="-2"
      upper="2"
      effort="0"
      velocity="0" />
  </joint>
</robot>